Workbook

Sheet Listas
A1: Aplicaciones | B1: Likert | C1: Valor
A2: Mi App Auna | B2: Totalmente en desacuerdo | C2: 1
A3: Aunados | B3: En desacuerdo | C3: 2
A4: Aunados - Facturación | B4: Ni de acuerdo ni en desacuerdo | C4: 3
A5: Aunados – Hospitalización | B5: De acuerdo | C5: 4
A6: Aunados – Devoluciones | B6: Totalmente de acuerdo | C6: 5
A7: Ecommerce Salud
A8: Teleconsultas
A9: Membresías Perú
A10: Auna.org
A11: Laboratorio B2B

Sheet Cuestionario Capacidades
A1: Cuestionario de Capacidades DORA Core
A2: Encuesta Likert · Basado en dora.dev/research (2022–2025) · Selecciona opciones desde los combos
A4: DATOS DEL EVALUADOR
A5: Nombre completo
A6: Aplicación / Servicio ▼
A8: AFIRMACIONES POR CAPACIDAD (escala Likert)
A9: Capacidad | B9: Afirmación | C9: Respuesta ▼ | D9: Valor | E9: Fuente DORA
A10: Mantenibilidad del código | B10: Es fácil para el equipo encontrar ejemplos en el código base, reutilizar código de otros y modificar código mantenido por otros equipos si es necesario. | D10: =IF(C10="","",INDEX(Listas!$C$2:$C$6,MATCH(C10,Listas!$B$2:$B$6,0))) | E10: DORA Capabilities Research
B11: Es fácil para el equipo agregar nuevas dependencias a su proyecto y migrar a una nueva versión de una dependencia. | D11: =IF(C11="","",INDEX(Listas!$C$2:$C$6,MATCH(C11,Listas!$B$2:$B$6,0)))
B12: Las dependencias del equipo son estables y rara vez rompen el código. | D12: =IF(C12="","",INDEX(Listas!$C$2:$C$6,MATCH(C12,Listas!$B$2:$B$6,0)))
A14: Entrega continua | B14: El feedback rápido sobre la calidad y desplegabilidad del sistema está disponible para cualquier persona del equipo. | D14: =IF(C14="","",INDEX(Listas!$C$2:$C$6,MATCH(C14,Listas!$B$2:$B$6,0))) | E14: DORA Research 2022 — Continuous Delivery
B15: Mi equipo prioriza mantener el software desplegable por encima de trabajar en nuevas funcionalidades. | D15: =IF(C15="","",INDEX(Listas!$C$2:$C$6,MATCH(C15,Listas!$B$2:$B$6,0)))
B16: Nuestro software se mantiene en un estado desplegable a lo largo de todo su ciclo de vida. | D16: =IF(C16="","",INDEX(Listas!$C$2:$C$6,MATCH(C16,Listas!$B$2:$B$6,0)))
B17: Podemos desplegar nuestro sistema a producción, o a los usuarios finales, en cualquier momento y bajo demanda. | D17: =IF(C17="","",INDEX(Listas!$C$2:$C$6,MATCH(C17,Listas!$B$2:$B$6,0)))
A19: Integración continua | B19: Los builds y tests automatizados se ejecutan con éxito todos los días. | D19: =IF(C19="","",INDEX(Listas!$C$2:$C$6,MATCH(C19,Listas!$B$2:$B$6,0))) | E19: DORA Research 2022 — Continuous Integration
B20: Los fallos en tests automatizados bloquearán el avance de un commit en el pipeline. | D20: =IF(C20="","",INDEX(Listas!$C$2:$C$6,MATCH(C20,Listas!$B$2:$B$6,0)))
B21: Los commits de código activan una serie de tests automatizados. | D21: =IF(C21="","",INDEX(Listas!$C$2:$C$6,MATCH(C21,Listas!$B$2:$B$6,0)))
B22: Los commits de código resultan en un build automatizado del software. | D22: =IF(C22="","",INDEX(Listas!$C$2:$C$6,MATCH(C22,Listas!$B$2:$B$6,0)))
A24: Gestión de cambios en base de datos | B24: Todos los cambios de base de datos se almacenan en control de versiones junto con el código de aplicación. | D24: =IF(C24="","",INDEX(Listas!$C$2:$C$6,MATCH(C24,Listas!$B$2:$B$6,0))) | E24: DORA Capabilities Research
B25: Existe una herramienta que registra qué cambios de base de datos se han ejecutado en cada entorno. | D25: =IF(C25="","",INDEX(Listas!$C$2:$C$6,MATCH(C25,Listas!$B$2:$B$6,0)))
B26: Los cambios de esquema de base de datos se prueban contra datos similares a producción antes del despliegue. | D26: =IF(C26="","",INDEX(Listas!$C$2:$C$6,MATCH(C26,Listas!$B$2:$B$6,0)))
A28: Automatización de despliegues | B28: Cualquier persona con las credenciales necesarias puede desplegar cualquier versión a cualquier entorno de forma totalmente automatizada. | D28: =IF(C28="","",INDEX(Listas!$C$2:$C$6,MATCH(C28,Listas!$B$2:$B$6,0))) | E28: DORA Capabilities Research
B29: Utilizamos el mismo proceso de despliegue para todos los entornos, incluida producción. | D29: =IF(C29="","",INDEX(Listas!$C$2:$C$6,MATCH(C29,Listas!$B$2:$B$6,0)))
B30: Utilizamos los mismos paquetes para todos los entornos, manteniendo la configuración específica separada. | D30: =IF(C30="","",INDEX(Listas!$C$2:$C$6,MATCH(C30,Listas!$B$2:$B$6,0)))
A32: Calidad de documentación | B32: Puedo confiar en nuestra documentación técnica cuando necesito usar o trabajar con los servicios o aplicaciones en los que trabajo. | D32: =IF(C32="","",INDEX(Listas!$C$2:$C$6,MATCH(C32,Listas!$B$2:$B$6,0))) | E32: DORA Research 2022 — Documentation
B33: Es fácil encontrar el documento técnico correcto cuando necesito entender algo sobre los servicios o aplicaciones en los que trabajo. | D33: =IF(C33="","",INDEX(Listas!$C$2:$C$6,MATCH(C33,Listas!$B$2:$B$6,0)))
B34: La documentación técnica se actualiza cuando se realizan cambios. | D34: =IF(C34="","",INDEX(Listas!$C$2:$C$6,MATCH(C34,Listas!$B$2:$B$6,0)))
B35: La documentación técnica refleja correctamente las capacidades y requisitos del servicio o aplicación principal en el que trabajo. | D35: =IF(C35="","",INDEX(Listas!$C$2:$C$6,MATCH(C35,Listas!$B$2:$B$6,0)))
A37: Empoderar equipos para elegir herramientas | B37: Nuestro equipo puede seleccionar herramientas que mejor se adapten a sus necesidades dentro de directrices organizacionales. | D37: =IF(C37="","",INDEX(Listas!$C$2:$C$6,MATCH(C37,Listas!$B$2:$B$6,0))) | E37: DORA Capabilities Research
B38: Se nos anima a experimentar con nuevas herramientas y compartir aprendizajes con otros equipos. | D38: =IF(C38="","",INDEX(Listas!$C$2:$C$6,MATCH(C38,Listas!$B$2:$B$6,0)))
B39: Existe un proceso documentado para evaluar y adoptar nuevas tecnologías fuera del conjunto base de herramientas. | D39: =IF(C39="","",INDEX(Listas!$C$2:$C$6,MATCH(C39,Listas!$B$2:$B$6,0)))
A41: Infraestructura flexible | B41: Puedo aumentar o disminuir dinámicamente los recursos en la nube disponibles para el servicio o producto que principalmente soporto según la demanda. | D41: =IF(C41="","",INDEX(Listas!$C$2:$C$6,MATCH(C41,Listas!$B$2:$B$6,0))) | E41: DORA Research 2022 — Cloud Computing
B42: Puedo monitorear o controlar la cantidad y/o el costo de los recursos en la nube utilizados por el servicio o producto que principalmente soporto. | D42: =IF(C42="","",INDEX(Listas!$C$2:$C$6,MATCH(C42,Listas!$B$2:$B$6,0)))
B43: Una vez que tengo acceso, puedo aprovisionar y configurar de forma independiente los recursos y capacidades en la nube requeridos para mi producto o servicio bajo demanda, sin crear tickets ni requerir interacción humana. | D43: =IF(C43="","",INDEX(Listas!$C$2:$C$6,MATCH(C43,Listas!$B$2:$B$6,0)))
B44: La nube en la que corre mi producto o servicio atiende a múltiples equipos y aplicaciones, con recursos de cómputo e infraestructura asignados y reasignados dinámicamente según la demanda. | D44: =IF(C44="","",INDEX(Listas!$C$2:$C$6,MATCH(C44,Listas!$B$2:$B$6,0)))
A46: Cultura organizacional generativa | B46: La colaboración entre funciones (cross-functional) es alentada y recompensada. | D46: =IF(C46="","",INDEX(Listas!$C$2:$C$6,MATCH(C46,Listas!$B$2:$B$6,0))) | E46: DORA Research 2022 — Generative Organizational Culture
B47: Los fallos se tratan principalmente como oportunidades para mejorar el sistema. | D47: =IF(C47="","",INDEX(Listas!$C$2:$C$6,MATCH(C47,Listas!$B$2:$B$6,0)))
B48: A los mensajeros no se les castiga cuando entregan noticias de fallos u otras malas noticias. | D48: =IF(C48="","",INDEX(Listas!$C$2:$C$6,MATCH(C48,Listas!$B$2:$B$6,0)))
B49: Las nuevas ideas son bienvenidas. | D49: =IF(C49="","",INDEX(Listas!$C$2:$C$6,MATCH(C49,Listas!$B$2:$B$6,0)))
A51: Satisfacción laboral | B51: Tengo las herramientas y recursos necesarios para realizar mi trabajo de forma efectiva. | D51: =IF(C51="","",INDEX(Listas!$C$2:$C$6,MATCH(C51,Listas!$B$2:$B$6,0))) | E51: DORA Capabilities Research
...

Sheet Instrucciones
A1: Instrucciones — Cuestionario Capacidades DORA Core
A3: 1. Ingresa tu nombre completo.
A4: 2. Selecciona la aplicación / servicio desde el combo.
A5: 3. Para cada afirmación, elige una opción Likert en la columna «Respuesta»:
A6: • Totalmente en desacuerdo
A7: • En desacuerdo
A8: • Ni de acuerdo ni en desacuerdo
A9: • De acuerdo
A10: • Totalmente de acuerdo
A11: 4. Los promedios por capacidad y la puntuación general se calculan automáticamente.
A13: Referencia: https://dora.dev/capabilities/
A14: Capacidades incluidas: 19 (modelo DORA Core)
